<mujoco model="ant">
    <compiler angle="degree" coordinate="local" inertiafromgeom="true" texturedir="textures"/>
    <option integrator="RK4" timestep="0.02"/>
    <custom>
        <numeric data="0.0 0.0 0.055 0.1 0.0 0.0 0.0 0.0 0.1 0.0 -0.1 0.0 -0.1 0.0 0.1" name="init_qpos"/>
    </custom>
    <default>
        <joint armature="1" damping="1" limited="true"/>
        <geom conaffinity="1" condim="3" density="5.0" friction="1 0.5 0.5" margin="0.01" rgba="0.8 0.6 0.4 1"/>
    </default>
    <asset>
        <texture type="skybox" file="sky.png" gridsize="3 4" gridlayout=".U..LFRB.D.."/>
        <texture builtin="flat" height="1278" mark="cross" markrgb="1 1 1" name="texgeom" random="0.01"
                 rgb1="0.8 0.6 0.4" rgb2="0.8 0.6 0.4" type="cube" width="127"/>
        <texture builtin="flat" height="100" name="texplane" rgb1="0.0 0.25 0.5" type="2d" width="100"/>
        <material name="MatPlane" shininess="1" specular="1" texrepeat="60 60" texture="texplane"/>
        <material name="geom" texture="texgeom" texuniform="true"/>
    </asset>
    <worldbody>
        <light cutoff="100" diffuse="1 1 1" dir="-0 0 -1.3" directional="true" exponent="1" pos="0 0 1.3"
               specular=".1 .1 .1"/>
        <geom conaffinity="1" condim="3" material="MatPlane" name="floor" pos="0 0 0" rgba="0.8 0.9 0.8 1"
              size="40 40 40" type="plane"/>
        <body name="torso" pos="0 0 0.075">
            <camera name="track" mode="trackcom" pos="0 -3 0.3" xyaxes="1 0 0 0 0 1"/>
            <geom name="torso_geom" pos="0 0 0" size="0.025" type="sphere"/>
            <joint armature="0" damping="0" limited="false" margin="0.01" name="root" pos="0 0 0" type="free"/>
            <body name="front_left_leg" pos="0 0 0">
                <geom fromto="0.0 0.0 0.0 0.02 0.02 0.0" name="aux_1_geom" size="0.008" type="capsule"/>
                <body name="up_leg1" pos="0.02 0.02 0">
                    <joint axis="0 0 1" name="hip_1" pos="0.0 0.0 0.0" range="-30 30" type="hinge"/>
                    <geom fromto="0.0 0.0 0.0 0.02 0.02 0.0" name="left_leg_geom" size="0.008" type="capsule"/>
                    <body name="low_leg1" pos="0.02 0.02 0">
                        <joint axis="-1 1 0" name="ankle_1" pos="0.0 0.0 0.0" range="30 70" type="hinge"/>
                        <geom fromto="0.0 0.0 0.0 0.04 0.04 0.0" name="left_ankle_geom" size="0.008" type="capsule"/>
                    </body>
                </body>
            </body>
            <body name="front_right_leg" pos="0 0 0">
                <geom fromto="0.0 0.0 0.0 -0.02 0.02 0.0" name="aux_2_geom" size="0.008" type="capsule"/>
                <body name="up_leg2" pos="-0.02 0.02 0">
                    <joint axis="0 0 1" name="hip_2" pos="0.0 0.0 0.0" range="-30 30" type="hinge"/>
                    <geom fromto="0.0 0.0 0.0 -0.02 0.02 0.0" name="right_leg_geom" size="0.008" type="capsule"/>
                    <body name="low_leg2" pos="-0.02 0.02 0">
                        <joint axis="1 1 0" name="ankle_2" pos="0.0 0.0 0.0" range="-70 -30" type="hinge"/>
                        <geom fromto="0.0 0.0 0.0 -0.04 0.04 0.0" name="right_ankle_geom" size="0.008" type="capsule"/>
                    </body>
                </body>
            </body>
            <body name="left_back_leg" pos="0 0 0">
                <geom fromto="0.0 0.0 0.0 -0.02 -0.02 0.0" name="aux_3_geom" size="0.008" type="capsule"/>
                <body name="up_leg3" pos="-0.02 -0.02 0">
                    <joint axis="0 0 1" name="hip_3" pos="0.0 0.0 0.0" range="-30 30" type="hinge"/>
                    <geom fromto="0.0 0.0 0.0 -0.02 -0.02 0.0" name="left_back_leg_geom" size="0.008" type="capsule"/>
                    <body name="low_leg3" pos="-0.02 -0.02 0">
                        <joint axis="-1 1 0" name="ankle_3" pos="0.0 0.0 0.0" range="-70 -30" type="hinge"/>
                        <geom fromto="0.0 0.0 0.0 -0.04 -0.04 0.0" name="left_back_ankle_geom" size="0.008"
                              type="capsule"/>
                    </body>
                </body>
            </body>
            <body name="right_back_leg" pos="0 0 0">
                <geom fromto="0.0 0.0 0.0 0.02 -0.02 0.0" name="aux_4_geom" size="0.008" type="capsule"/>
                <body name="up_leg4" pos="0.02 -0.02 0">
                    <joint axis="0 0 1" name="hip_4" pos="0.0 0.0 0.0" range="-30 30" type="hinge"/>
                    <geom fromto="0.0 0.0 0.0 0.02 -0.02 0.0" name="right_back_leg_geom" size="0.008" type="capsule"/>
                    <body name="low_leg4" pos="0.02 -0.02 0">
                        <joint axis="1 1 0" name="ankle_4" pos="0.0 0.0 0.0" range="30 70" type="hinge"/>
                        <geom fromto="0.0 0.0 0.0 0.04 -0.04 0.0" name="right_back_ankle_geom" size="0.008"
                              type="capsule"/>
                    </body>
                </body>
            </body>
        </body>

        <!-- Create Barriers -->
        <body name="east_wall" pos="0.825 0 0.1">
            <geom type="box" size="0.025 0.825 0.1" contype="1" conaffinity="1" rgba="0.4 0.4 0.4 1"/>
        </body>
        <body name="north_wall" pos="0 0.825 0.1">
            <geom type="box" size="0.85 0.025 0.1" contype="1" conaffinity="1" rgba="0.4 0.4 0.4 1"/>
        </body>
        <body name="west_wall" pos="-0.825 0 0.1">
            <geom type="box" size="0.025 0.825 0.1" contype="1" conaffinity="1" rgba="0.4 0.4 0.4 1"/>
        </body>
        <body name="south_wall" pos="0 -0.825 0.1">
            <geom type="box" size="0.85 0.025 0.1" contype="1" conaffinity="1" rgba="0.4 0.4 0.4 1"/>
        </body>

        <!-- cage -->
        <body name="cage" pos="0.85 0.25 0">
            <joint armature="0" damping="0" limited="false" margin="0.01" name="cage:joint" pos="0 0 0" type="free"/>
            <geom name="cage:botback" type="box" condim="1" pos="0 0.1 0.001" size="0.11 0.01 0.001" mass="1000000"
                  rgba="0.8 0.8 0.81 1"/>
            <geom name="cage:botfront" type="box" condim="1" pos="0 -0.1 0.001" size="0.11 0.01 0.001" mass="1000000"
                  rgba="0.8 0.8 0.81 1"/>
            <geom name="cage:botleft" type="box" condim="1" pos="-0.1 0 0.001" size="0.01 0.11 0.001" mass="1000000"
                  rgba="0.8 0.8 0.81 1"/>
            <geom name="cage:botright" type="box" condim="1" pos="0.1 0 0.001" size="0.01 0.11 0.001" mass="1000000"
                  rgba="0.8 0.8 0.81 1"/>
            <body name="cage:glass" pos="0 0.1 0.0021">
                <joint armature="0" damping="0" name="cage:glassjoint" type="hinge" axis="1 0 0" pos="0 0 0"
                       limited="false" range="-1.5708 0" margin="0.01"/>
                <geom name="cage:glassback" type="box" condim="1" pos="0 -0.02 0.02" size="0.06 0.02 0.02" mass="100"
                      rgba="0.8 0.8 0.81 0"/>
                <geom name="cage:glassfront" type="box" condim="1" pos="0 -0.18 0.02" size="0.06 0.02 0.02" mass="100"
                      rgba="0.8 0.8 0.81 0"/>
                <geom name="cage:glassleft" type="box" condim="1" pos="-0.08 -0.1 0.02" size="0.02 0.1 0.02" mass="100"
                      rgba="0.8 0.8 0.81 0"/>
                <geom name="cage:glassright" type="box" condim="1" pos="0.08 -0.1 0.02" size="0.02 0.1 0.02" mass="100"
                      rgba="0.8 0.8 0.81 0"/>
                <geom name="cage:glasstop" type="box" condim="1" pos="0 -0.1 0.07" size="0.1 0.1 0.03" mass="10"
                      rgba="0.8 0.8 0.81 0"/>
                <geom name="cage:glassback_visible" type="box" condim="3" pos="0 0 0.051" size="0.102 0.002 0.05"
                      mass="1000" rgba="0.8 0.8 0.81 0.3"/>
                <geom name="cage:glassfront_visible" type="box" condim="3" pos="0 -0.2 0.051" size="0.102 0.002 0.05"
                      mass="1000" rgba="0.8 0.8 0.81 0.3"/>
                <geom name="cage:glassleft_visible" type="box" condim="3" pos="-0.1 -0.1 0.051" size="0.002 0.102 0.05"
                      mass="1000" rgba="0.8 0.8 0.81 0.3"/>
                <geom name="cage:glassright_visible" type="box" condim="3" pos="0.1 -0.1 0.051" size="0.002 0.102 0.05"
                      mass="1000" rgba="0.8 0.8 0.81 0.3"/>
                <geom name="cage:glasstop_visible" type="box" condim="3" pos="0 -0.1 0.1" size="0.1 0.1 0.002"
                      mass="200" rgba="0.8 0.8 0.81 0.3"/>
            </body>
        </body>

        <!-- goal object-->
        <body name="object0" pos="0 1 0.025">
            <joint armature="0" damping="0" limited="false" margin="0.01" name="object0:joint" pos="0 0 0" type="free"/>
            <geom size="0.025 0.01" type="cylinder" condim="3" name="object0" rgba="1 0 0 1" mass="1000000"/>
        </body>

        <!-- buttons-->
        <body name="object1" pos="0 0.92 0.025">
            <joint armature="0" damping="0" limited="false" margin="0.01" name="object1:joint" pos="0 0 0" type="free"/>
            <geom size="0.022 0.022 0.008" type="ellipsoid" condim="3" name="object1" rgba="0.1 0.1 0.9 1"
                  mass="1000000"/>
            <geom size="0.025 0.006" type="cylinder" condim="3" name="frame1" rgba="0.8 0.8 0.81 1" mass="1000000"
                  pos="0 0 -0.003"/>
        </body>
        <body name="object2" pos="0.1  0.92 0.025">
            <joint armature="0" damping="0" limited="false" margin="0.01" name="object2:joint" pos="0 0 0" type="free"/>
            <geom size="0.022 0.022 0.008" type="ellipsoid" condim="3" name="object2" rgba="0.1 0.1 0.9 1"
                  mass="1000000"/>
            <geom size="0.025 0.006" type="cylinder" condim="3" name="frame2" rgba="0.8 0.8 0.81 1" mass="1000000"
                  pos="0 0 -0.003"/>
        </body>
    </worldbody>

    <actuator>
        <motor ctrllimited="true" ctrlrange="-1.0 1.0" joint="hip_4" gear="15"/>
        <motor ctrllimited="true" ctrlrange="-1.0 1.0" joint="ankle_4" gear="15"/>
        <motor ctrllimited="true" ctrlrange="-1.0 1.0" joint="hip_1" gear="15"/>
        <motor ctrllimited="true" ctrlrange="-1.0 1.0" joint="ankle_1" gear="15"/>
        <motor ctrllimited="true" ctrlrange="-1.0 1.0" joint="hip_2" gear="15"/>
        <motor ctrllimited="true" ctrlrange="-1.0 1.0" joint="ankle_2" gear="15"/>
        <motor ctrllimited="true" ctrlrange="-1.0 1.0" joint="hip_3" gear="15"/>
        <motor ctrllimited="true" ctrlrange="-1.0 1.0" joint="ankle_3" gear="15"/>
    </actuator>
</mujoco>
