<?xml version="1.0" encoding="utf-8"?>
<mujoco>
	<compiler angle="radian" coordinate="local" meshdir="stls/fetch"/>
	<option timestep="0.002">
		<flag warmstart="enable"/>
	</option>

	<include file="shared.xml"/>
	
	<worldbody>
		<geom name="floor0" pos="-0.25 0 0" size="0.8 0.7 1" type="plane" condim="3" material="floor_mat"/>
		<body name="floor0" pos="0 0 0"/>

		<include file="robot.xml"/>

		<body pos="0 0 0.2" name="table0">
			<geom size="0.3 0.3 0.2" type="box" mass="2000" material="table_mat"/>
		</body>

		<!-- buttons -->
		<body name="object0" pos="-0.2 0.2 0.016">
			<joint name="object0:joint" type="free" damping="0.01"/>
            <geom size="0.022 0.022 0.008" type="ellipsoid" condim="3" name="object0" material="block_mat" rgba="0.9 0.1 0.1 1" mass="1000000"/>
			<geom size="0.025 0.006" type="cylinder" condim="3" name="frame0" material="block_mat" rgba="0.8 0.8 0.81 1" mass="1000000" pos="0 0 -0.003"/>
		</body>
		<body name="object1" pos="-0.2 0 0.016">
			<joint name="object1:joint" type="free" damping="0.01"/>
            <geom size="0.022 0.022 0.008" type="ellipsoid" condim="3" name="object1" material="block_mat" rgba="0.1 0.1 0.9 1" mass="1000000"/>
			<geom size="0.025 0.006" type="cylinder" condim="3" name="frame1" material="block_mat" rgba="0.8 0.8 0.81 1" mass="1000000" pos="0 0 -0.003"/>
		</body>
		<body name="object2" pos="0 -0.2 0.016">
			<joint name="object2:joint" type="free" damping="0.01"/>
            <geom size="0.022 0.022 0.008" type="ellipsoid" condim="3" name="object2" material="block_mat" rgba="0.1 0.1 0.9 1" mass="1000000"/>
			<geom size="0.025 0.006" type="cylinder" condim="3" name="frame2" material="block_mat" rgba="0.8 0.8 0.81 1" mass="1000000" pos="0 0 -0.003"/>
		</body>

		<body name="cage" pos="0 0 0.45">
			<joint name="cage:joint" type="free"/>
			<geom name="cage:botback" type="box" condim="3" pos="0 0.05 -0.045" size="0.055 0.005 0.005" mass="1000000" rgba="0.8 0.8 0.81 1"/>
			<geom name="cage:botfront" type="box" condim="3" pos="0 -0.05 -0.045" size="0.055 0.005 0.005" mass="1000000" rgba="0.8 0.8 0.81 1"/>
			<geom name="cage:botleft" type="box" condim="3" pos="-0.05 0 -0.045" size="0.005 0.055 0.005" mass="1000000" rgba="0.8 0.8 0.81 1"/>
			<geom name="cage:botright" type="box" condim="3" pos="0.05 0 -0.045" size="0.005 0.055 0.005" mass="1000000" rgba="0.8 0.8 0.81 1"/>
			<body name="cage:glass" pos="0 0.05 -0.04">
				<joint name="cage:glassjoint" type="hinge" axis="1 0 0" pos="0 0 0" limited="true" range="-2 0"/>
				<geom name="cage:glassback" type="box" condim="3" pos="0 0 0.0255" size="0.051 0.001 0.025" mass="1000" rgba="0.8 0.8 0.81 0.3"/>
				<geom name="cage:glassfront" type="box" condim="3" pos="0 -0.1 0.0255" size="0.051 0.001 0.025" mass="1000" rgba="0.8 0.8 0.81 0.3"/>
				<geom name="cage:glassleft" type="box" condim="3" pos="-0.05 -0.05 0.0255" size="0.001 0.051 0.025" mass="1000" rgba="0.8 0.8 0.81 0.3"/>
				<geom name="cage:glassright" type="box" condim="3" pos="0.05 -0.05 0.0255" size="0.001 0.051 0.025" mass="1000" rgba="0.8 0.8 0.81 0.3"/>
				<geom name="cage:glasstop" type="box" condim="3" pos="0 -0.05 0.05" size="0.05 0.05 0.001" mass="200" rgba="0.8 0.8 0.81 0.3"/>
			</body>
		</body>

		<light directional="true" ambient="0.2 0.2 0.2" diffuse="0.8 0.8 0.8" specular="0.3 0.3 0.3" castshadow="false" pos="0 0 4" dir="0 0 -1" name="light0"/>
	</worldbody>
</mujoco>
